Failure # 1 (occurred at 2022-10-21_17-37-47)
Traceback (most recent call last):
  File "G:\Anaconda3\envs\CoPO\lib\site-packages\ray\tune\trial_runner.py", line 586, in _process_trial
    results = self.trial_executor.fetch_result(trial)
  File "G:\Anaconda3\envs\CoPO\lib\site-packages\ray\tune\ray_trial_executor.py", line 609, in fetch_result
    result = ray.get(trial_future[0], timeout=DEFAULT_GET_TIMEOUT)
  File "G:\Anaconda3\envs\CoPO\lib\site-packages\ray\_private\client_mode_hook.py", line 47, in wrapper
    return func(*args, **kwargs)
  File "G:\Anaconda3\envs\CoPO\lib\site-packages\ray\worker.py", line 1456, in get
    raise value.as_instanceof_cause()
ray.exceptions.RayTaskError(ValueError): [36mray::QMIX.train_buffered()[39m (pid=4072, ip=192.168.1.101)
  File "python\ray\_raylet.pyx", line 439, in ray._raylet.execute_task
  File "G:\Anaconda3\envs\CoPO\lib\site-packages\ray\worker.py", line 176, in reraise_actor_init_error
    raise self.actor_init_error
  File "python\ray\_raylet.pyx", line 473, in ray._raylet.execute_task
  File "python\ray\_raylet.pyx", line 476, in ray._raylet.execute_task
  File "python\ray\_raylet.pyx", line 480, in ray._raylet.execute_task
  File "python\ray\_raylet.pyx", line 432, in ray._raylet.execute_task.function_executor
  File "G:\Anaconda3\envs\CoPO\lib\site-packages\ray\function_manager.py", line 556, in actor_method_executor
    return method(__ray_actor, *args, **kwargs)
  File "G:\Anaconda3\envs\CoPO\lib\site-packages\ray\rllib\agents\trainer_template.py", line 107, in __init__
    Trainer.__init__(self, config, env, logger_creator)
  File "G:\Anaconda3\envs\CoPO\lib\site-packages\ray\rllib\agents\trainer.py", line 486, in __init__
    super().__init__(config, logger_creator)
  File "G:\Anaconda3\envs\CoPO\lib\site-packages\ray\tune\trainable.py", line 97, in __init__
    self.setup(copy.deepcopy(self.config))
  File "G:\Anaconda3\envs\CoPO\lib\site-packages\ray\rllib\agents\trainer.py", line 654, in setup
    self._init(self.config, self.env_creator)
  File "G:\Anaconda3\envs\CoPO\lib\site-packages\ray\rllib\agents\trainer_template.py", line 134, in _init
    self.workers = self._make_workers(
  File "G:\Anaconda3\envs\CoPO\lib\site-packages\ray\rllib\agents\trainer.py", line 725, in _make_workers
    return WorkerSet(
  File "G:\Anaconda3\envs\CoPO\lib\site-packages\ray\rllib\evaluation\worker_set.py", line 90, in __init__
    self._local_worker = self._make_worker(
  File "G:\Anaconda3\envs\CoPO\lib\site-packages\ray\rllib\evaluation\worker_set.py", line 321, in _make_worker
    worker = cls(
  File "G:\Anaconda3\envs\CoPO\lib\site-packages\ray\rllib\evaluation\rollout_worker.py", line 479, in __init__
    self.policy_map, self.preprocessors = self._build_policy_map(
  File "G:\Anaconda3\envs\CoPO\lib\site-packages\ray\rllib\evaluation\rollout_worker.py", line 1108, in _build_policy_map
    policy_map[name] = cls(obs_space, act_space, merged_conf)
  File "G:\Anaconda3\envs\CoPO\lib\site-packages\ray\rllib\agents\qmix\qmix_policy.py", line 160, in __init__
    _validate(obs_space, action_space)
  File "G:\Anaconda3\envs\CoPO\lib\site-packages\ray\rllib\agents\qmix\qmix_policy.py", line 508, in _validate
    raise ValueError("Obs space must be a Tuple, got {}. Use ".format(
ValueError: Obs space must be a Tuple, got Box([-1. -1. -1. ... -1. -1. -1.], [1. 1. 1. ... 1. 1. 1.], (2730,), float32). Use MultiAgentEnv.with_agent_groups() to group related agents for QMix.

Failure # 2 (occurred at 2022-10-21_17-37-49)
Traceback (most recent call last):
  File "G:\Anaconda3\envs\CoPO\lib\site-packages\ray\tune\trial_runner.py", line 586, in _process_trial
    results = self.trial_executor.fetch_result(trial)
  File "G:\Anaconda3\envs\CoPO\lib\site-packages\ray\tune\ray_trial_executor.py", line 609, in fetch_result
    result = ray.get(trial_future[0], timeout=DEFAULT_GET_TIMEOUT)
  File "G:\Anaconda3\envs\CoPO\lib\site-packages\ray\_private\client_mode_hook.py", line 47, in wrapper
    return func(*args, **kwargs)
  File "G:\Anaconda3\envs\CoPO\lib\site-packages\ray\worker.py", line 1456, in get
    raise value.as_instanceof_cause()
ray.exceptions.RayTaskError(ValueError): [36mray::QMIX.train_buffered()[39m (pid=9268, ip=192.168.1.101)
  File "python\ray\_raylet.pyx", line 439, in ray._raylet.execute_task
  File "G:\Anaconda3\envs\CoPO\lib\site-packages\ray\worker.py", line 176, in reraise_actor_init_error
    raise self.actor_init_error
  File "python\ray\_raylet.pyx", line 473, in ray._raylet.execute_task
  File "python\ray\_raylet.pyx", line 476, in ray._raylet.execute_task
  File "python\ray\_raylet.pyx", line 480, in ray._raylet.execute_task
  File "python\ray\_raylet.pyx", line 432, in ray._raylet.execute_task.function_executor
  File "G:\Anaconda3\envs\CoPO\lib\site-packages\ray\function_manager.py", line 556, in actor_method_executor
    return method(__ray_actor, *args, **kwargs)
  File "G:\Anaconda3\envs\CoPO\lib\site-packages\ray\rllib\agents\trainer_template.py", line 107, in __init__
    Trainer.__init__(self, config, env, logger_creator)
  File "G:\Anaconda3\envs\CoPO\lib\site-packages\ray\rllib\agents\trainer.py", line 486, in __init__
    super().__init__(config, logger_creator)
  File "G:\Anaconda3\envs\CoPO\lib\site-packages\ray\tune\trainable.py", line 97, in __init__
    self.setup(copy.deepcopy(self.config))
  File "G:\Anaconda3\envs\CoPO\lib\site-packages\ray\rllib\agents\trainer.py", line 654, in setup
    self._init(self.config, self.env_creator)
  File "G:\Anaconda3\envs\CoPO\lib\site-packages\ray\rllib\agents\trainer_template.py", line 134, in _init
    self.workers = self._make_workers(
  File "G:\Anaconda3\envs\CoPO\lib\site-packages\ray\rllib\agents\trainer.py", line 725, in _make_workers
    return WorkerSet(
  File "G:\Anaconda3\envs\CoPO\lib\site-packages\ray\rllib\evaluation\worker_set.py", line 90, in __init__
    self._local_worker = self._make_worker(
  File "G:\Anaconda3\envs\CoPO\lib\site-packages\ray\rllib\evaluation\worker_set.py", line 321, in _make_worker
    worker = cls(
  File "G:\Anaconda3\envs\CoPO\lib\site-packages\ray\rllib\evaluation\rollout_worker.py", line 479, in __init__
    self.policy_map, self.preprocessors = self._build_policy_map(
  File "G:\Anaconda3\envs\CoPO\lib\site-packages\ray\rllib\evaluation\rollout_worker.py", line 1108, in _build_policy_map
    policy_map[name] = cls(obs_space, act_space, merged_conf)
  File "G:\Anaconda3\envs\CoPO\lib\site-packages\ray\rllib\agents\qmix\qmix_policy.py", line 160, in __init__
    _validate(obs_space, action_space)
  File "G:\Anaconda3\envs\CoPO\lib\site-packages\ray\rllib\agents\qmix\qmix_policy.py", line 508, in _validate
    raise ValueError("Obs space must be a Tuple, got {}. Use ".format(
ValueError: Obs space must be a Tuple, got Box([-1. -1. -1. ... -1. -1. -1.], [1. 1. 1. ... 1. 1. 1.], (2730,), float32). Use MultiAgentEnv.with_agent_groups() to group related agents for QMix.

